2019-12-27 17:00:40,307 :: Exception Decorator :: ERROR :: There was an exception in divide
Traceback (most recent call last):
  File "D:\code_snippets\Decorators\exception_decorator.py", line 22, in wrapper
    return fun(*args, **kwargs)
  File "D:/code_snippets/Decorators/divide.py", line 6, in divide
    return 1/0
ZeroDivisionError: division by zero
